Workbook

Sheet Produção
B2: CONTROLE DE PRODUÇÃO
B4: Campanhas realizadas no mês de outubro 2017
B5: Lote | C5: Piloto | D5: [ ] | E5: Campanha | F5: Descrição | G5: Objetivo
B6: 20171003Pa | C6: P50 | D6: 50g/L | E6: RHODIA | F6: Processamento padrão em série | G6: Lote para testes de aplicação em potencial cliente : RHODIA
B7: 20171010Pa | C7: P50 | D7: 50g/L | E7: RHODIA | F7: Processamento padrão em série | G7: Lote para testes de aplicação em potencial cliente : RHODIA
B8: 20171013Pa | C8: P50 | D8: 50g/L | E8: RHODIA | F8: Processamento padrão em série | G8: Lote para testes de aplicação em potencial cliente : RHODIA
B9: Campanhas realizadas no mês de novembro 2017
B10: Lote | C10: Piloto | D10: [ ] | E10: Campanha | F10: Descrição | G10: Objetivo
B11: 20171112Pa | C11: P50 | D11: 50g/L | F11: Processamento padrão em série | G11: Lote para testes de otimização de centrifugação em bancada ( Frente Bancada )
B12: 20171120Pa | C12: P25 | D12: 100g/L | F12: Teste operacional com aumento da [ ] = 100g/L | G12: Avaliação da capacidade de processamento do equipamento silverson VERSO com aumento da concentração inicial de grafite para 100g/L
B13: 20171124Pa | C13: P50 | D13: 50g/L | F13: Startup Centrifuga Decanter | G13: Testes conceito com equipamendo alugado ( OMEGALINE ) 2000 L/h
B14: Campanhas realizadas no mês de dezembro 2017
B15: Lote | C15: Piloto | D15: [ ] | E15: Campanha | F15: Descrição | G15: Objetivo
B16: 20171227Pa | C16: P50 | D16: 50g/L | E16: KATRINA | F16: Processamento padrão em série | G16: Lote padrão P50 em série para testes de flotação em coluna
B17: 20171228Pa | C17: P50 | D17: 50g/L | E17: KATRINA | F17: Processamento padrão em série | G17: Lote padrão P50 em série para testes de flotação em coluna
B18: Campanhas realizadas no mês de janeiro 2018
B19: Lote | C19: Piloto | D19: [ ] | E19: Campanha | F19: Descrição | G19: Objetivo
B20: 20180102Pa | C20: P50 | D20: 50g/L | E20: KATRINA | F20: Processamento padrão em série | G20: Lote padrão P50 em série para testes de flotação em coluna
B21: 20180103Pa | C21: P50 | D21: 50g/L | E21: KATRINA | F21: Processamento padrão em série | G21: Lote padrão P50 em série para testes de flotação em coluna
B22: 20180108Pa | C22: P50 | D22: 50g/L | E22: KATRINA | F22: Homogeinização da campanha KATRINA | G22: Homogeinização de 200L gerados na campanha KATRINA para testes de flotação em coluna / Portifólio 01
B23: 20180130Pa | C23: P25 | D23: 100g/L | F23: Teste piloto IKA | G23: Avaliar curva de rendimento com equipamento alugado da IKA
B24: Campanhas realizadas no mês de fevereiro 2018
B25: Lote | C25: Piloto | D25: [ ] | E25: Campanha | F25: Descrição | G25: Objetivo
B26: 20180220Pa | C26: P5 | D26: 50g/L | F26: Avaliação da reprodutibilidade | G26: Avaliar reprodutibilidade na escala piloto P5 até 5 litros ( Frente Caracterização )
B27: Campanhas realizadas no mês de março 2018
B28: Lote | C28: Piloto | D28: [ ] | E28: Campanha | F28: Descrição | G28: Objetivo
B29: 20180312Pa | C29: P5 | D29: 50g/L | F29: Teste de selo mecânico nacional - Silverson Verso | G29: Busca de fornecedor alternativo para selos mecânicos para o equipamento silverson VERSO
B30: 20180313Pa | C30: P50 | D30: 50g/L | F30: Processamento padrão em série | G30: Para testes de flotação em bancada
B31: 20180321Pa | C31: P100 | D31: 50g/L | F31: Startup Konmix - 3.550rpm | G31: Startup Konmix para adequação das condições operações
B32: Campanhas realizadas no mês de abril 2018
B33: Lote | C33: Piloto | D33: [ ] | E33: Campanha | F33: Descrição | G33: Objetivo
B34: 20180402Pa | C34: P100 | D34: 50g/L | F34: Startup Silverson UHS 175/275 – 3.600rpm | G34: Startup Silverson para adequação das condições operações
B35: 20180417Pa | C35: P100 | D35: 50g/L | E35: IRENE | F35: Silverson UHS 175/275 – 3.600rpm | G35: Curva de rendimento do Silverson UHS 175/275 - 3.600rpm
B36: 20180417Pb | C36: P100 | D36: 50g/L | E36: IRENE | F36: Konmix – 3.550rpm | G36: Curva de rendimento do Konmix- 3.550rpm
B37: 20180424Pa | C37: P100 | D37: 50g/L | F37: Silverson UHS 175/275 – 6.000rpm | G37: Curva de rendimento do Silverson UHS 175/275 - 6.000rpm
B38: Campanhas realizadas no mês de maio 2018
B39: Lote | C39: Piloto | D39: [ ] | F39: Descrição | G39: Objetivo
B40: 20180502Pa | C40: P50 | D40: 50g/L | F40: 1 Ciclo / Uma passagem / Um cisalhador | G40: Avaliar se há diferenças em relação ao tamanho de partícula obtido com apenas uma passagem do material pelo cisalhador
B41: 20180507Pa | C41: P50 | D41: 50g/L | F41: Processamento padrão em série | G41: Produzir amostras centrifugada e não centrifugada para testes de flotação em escala de bancada
B42: 20180511Pa | C42: P10 | D42: 50g/L | F42: Análise de carregamento de grafite expandido | G42: (1)Avaliar o método de carregamento e fazer estimativa da carga máxima que poderia ser alcançada em tanques; (2) Avaliar processamento da dispersão quando submetida a processamento com o equipamento tipo inline (Verso).
...

Sheet Acabamento
A1: CONTROLE DE PRODUÇÃO
A3: Lote | B3: Piloto | C3: [ ] | D3: Campanha | E3: Processo de acabamento
A4: =Produção!B164 -> 20211025Pa | B4: =Produção!C164 -> P100 | C4: =Produção!D164 -> 100 g/L | D4: =Produção!E164 -> Prod. Cont. Camp. 01 | E4: Liofilização (Entrega parceiros)
A5: =Produção!B165 -> 20211108Pa | B5: =Produção!C165 -> P100 | C5: =Produção!D165 -> 50 g/L | D5: =Produção!E165 -> 0 | E5: Entrega para Caracterização
A6: =Produção!B166 -> 20211116Pa | B6: =Produção!C166 -> P100 | C6: =Produção!D166 -> 100g/L | D6: =Produção!E166 -> Prod. Cont. Camp. 01 | E6: Concentração
A7: =Produção!B167 -> 20211122Pa | B7: =Produção!C167 -> P100 | C7: =Produção!D167 -> 100g/L | D7: =Produção!E167 -> Prod. Cont. Camp. 01 | E7: Concentração
A8: =Produção!B168 -> 20211124Pa | B8: =Produção!C168 -> P100 | C8: =Produção!D168 -> 100g/L | D8: =Produção!E168 -> Prod. Cont. Camp. 01 | E8: -
A9: =Produção!B169 -> 20211129Pa | B9: =Produção!C169 -> P100 | C9: =Produção!D169 -> 100g/L | D9: =Produção!E169 -> Prod. Cont. Camp. 01 | E9: Concentração
A10: =Produção!B170 -> 20211201Pa | B10: =Produção!C170 -> P100 | C10: =Produção!D170 -> 100g/L | D10: =Produção!E170 -> Prod. Cont. Camp. 01 | E10: -
A11: =Produção!B171 -> 20211206Pa | B11: =Produção!C171 -> P100 | C11: =Produção!D171 -> 100g/L | D11: =Produção!E171 -> Prod. Cont. Camp. 01
A12: =Produção!B172 -> 20211214Pa | B12: =Produção!C172 -> P100 | C12: =Produção!D172 -> 100g/L | D12: =Produção!E172 -> Prod. Cont. Camp. 01
A13: =Produção!B174 -> 20220118Pa | B13: =Produção!C174 -> P100 | C13: =Produção!D174 -> 100g/L | D13: =Produção!E174 -> Prod. Cont. Camp. 01 | E13: Concentração
A14: =Produção!B176 -> 20220208Pa | B14: =Produção!C176 -> P100 | C14: =Produção!D176 -> 100g/L | D14: =Produção!E176 -> 0
A15: =Produção!B177 -> 20220214Pa | B15: =Produção!C177 -> P100 | C15: =Produção!D177 -> 100g/L | D15: =Produção!E177 -> Prod. Cont. Camp. 02
A16: =Produção!B178 -> 20220221Pa | B16: =Produção!C178 -> P100 | C16: =Produção!D178 -> 100g/L | D16: =Produção!E178 -> Prod. Cont. Camp. 02
A17: =Produção!B179 -> 20220307Pa | B17: =Produção!C179 -> P100 | C17: =Produção!D179 -> 100g/L | D17: =Produção!E179 -> Prod. Cont. Camp. 02
A18: =Produção!B180 -> 0 | B18: =Produção!C180 -> 0 | C18: =Produção!D180 -> 0 | D18: =Produção!E180 -> 0
A19: =Produção!B181 -> 0 | B19: =Produção!C181 -> 0 | C19: =Produção!D181 -> 0 | D19: =Produção!E181 -> 0
A20: =Produção!B182 -> 0 | B20: =Produção!C182 -> 0 | C20: =Produção!D182 -> 0 | D20: =Produção!E182 -> 0
A21: =Produção!B183 -> 0 | B21: =Produção!C183 -> 0 | C21: =Produção!D183 -> 0 | D21: =Produção!E183 -> 0
A22: =Produção!B184 -> 0 | B22: =Produção!C184 -> 0 | C22: =Produção!D184 -> 0 | D22: =Produção!E184 -> 0
A23: =Produção!B185 -> 0 | B23: =Produção!C185 -> 0 | C23: =Produção!D185 -> 0 | D23: =Produção!E185 -> 0
A24: =Produção!B186 -> 0 | B24: =Produção!C186 -> 0 | C24: =Produção!D186 -> 0 | D24: =Produção!E186 -> 0
A25: =Produção!B187 -> 0 | B25: =Produção!C187 -> 0 | C25: =Produção!D187 -> 0 | D25: =Produção!E187 -> 0
... A251: =Produção!B413 -> 0 | B251: =Produção!C413 -> 0 | C251: =Produção!D413 -> 0 | D251: =Produção!E413 -> 0

Sheet Formularios
A1: Controle de formulários
A2: Lote | B2: Piloto | C2: [ ] | D2: Descrição | E2: Formulário de análise
E3: Conversão | F3: Separação | G3: Acabamento
A4: =Produção!B6 -> 20171003Pa | B4: =Produção!C6 -> P50 | C4: =Produção!D6 -> 50g/L | D4: =Produção!F6 -> Processamento padrão em série
A5: =Produção!B7 -> 20171010Pa | B5: =Produção!C7 -> P50 | C5: =Produção!D7 -> 50g/L | D5: =Produção!F7 -> Processamento padrão em série
A6: =Produção!B8 -> 20171013Pa | B6: =Produção!C8 -> P50 | C6: =Produção!D8 -> 50g/L | D6: =Produção!F8 -> Processamento padrão em série
A7: =Produção!B11 -> 20171112Pa | B7: =Produção!C11 -> P50 | C7: =Produção!D11 -> 50g/L | D7: =Produção!F11 -> Processamento padrão em série
A8: =Produção!B12 -> 20171120Pa | B8: =Produção!C12 -> P25 | C8: =Produção!D12 -> 100g/L | D8: =Produção!F12 -> Teste operacional com aumento da [ ] = 100g/L
A9: =Produção!B13 -> 20171124Pa | B9: =Produção!C13 -> P50 | C9: =Produção!D13 -> 50g/L | D9: =Produção!F13 -> Startup Centrifuga Decanter
A10: =Produção!B16 -> 20171227Pa | B10: =Produção!C16 -> P50 | C10: =Produção!D16 -> 50g/L | D10: =Produção!F16 -> Processamento padrão em série
A11: =Produção!B17 -> 20171228Pa | B11: =Produção!C17 -> P50 | C11: =Produção!D17 -> 50g/L | D11: =Produção!F17 -> Processamento padrão em série
A12: =Produção!B20 -> 20180102Pa | B12: =Produção!C20 -> P50 | C12: =Produção!D20 -> 50g/L | D12: =Produção!F20 -> Processamento padrão em série
A13: =Produção!B21 -> 20180103Pa | B13: =Produção!C21 -> P50 | C13: =Produção!D21 -> 50g/L | D13: =Produção!F21 -> Processamento padrão em série
A14: =Produção!B22 -> 20180108Pa | B14: =Produção!C22 -> P50 | C14: =Produção!D22 -> 50g/L | D14: =Produção!F22 -> Homogeinização da campanha KATRINA
A15: =Produção!B23 -> 20180130Pa | B15: =Produção!C23 -> P25 | C15: =Produção!D23 -> 100g/L | D15: =Produção!F23 -> Teste piloto IKA
A16: =Produção!B26 -> 20180220Pa | B16: =Produção!C26 -> P5 | C16: =Produção!D26 -> 50g/L | D16: =Produção!F26 -> Avaliação da reprodutibilidade
A17: =Produção!B29 -> 20180312Pa | B17: =Produção!C29 -> P5 | C17: =Produção!D29 -> 50g/L | D17: =Produção!F29 -> Teste de selo mecânico nacional - Silverson Verso
A18: =Produção!B30 -> 20180313Pa | B18: =Produção!C30 -> P50 | C18: =Produção!D30 -> 50g/L | D18: =Produção!F30 -> Processamento padrão em série
A19: =Produção!B31 -> 20180321Pa | B19: =Produção!C31 -> P100 | C19: =Produção!D31 -> 50g/L | D19: =Produção!F31 -> Startup Konmix - 3.550rpm
A20: =Produção!B34 -> 20180402Pa | B20: =Produção!C34 -> P100 | C20: =Produção!D34 -> 50g/L | D20: =Produção!F34 -> Startup Silverson UHS 175/275 – 3.600rpm
A21: =Produção!B35 -> 20180417Pa | B21: =Produção!C35 -> P100 | C21: =Produção!D35 -> 50g/L | D21: =Produção!F35 -> Silverson UHS 175/275 – 3.600rpm
A22: =Produção!B36 -> 20180417Pb | B22: =Produção!C36 -> P100 | C22: =Produção!D36 -> 50g/L | D22: =Produção!F36 -> Konmix – 3.550rpm
A23: =Produção!B37 -> 20180424Pa | B23: =Produção!C37 -> P100 | C23: =Produção!D37 -> 50g/L | D23: =Produção!F37 -> Silverson UHS 175/275 – 6.000rpm
A24: =Produção!B40 -> 20180502Pa | B24: =Produção!C40 -> P50 | C24: =Produção!D40 -> 50g/L | D24: =Produção!F40 -> 1 Ciclo / Uma passagem / Um cisalhador
A25: =Produção!B41 -> 20180507Pa | B25: =Produção!C41 -> P50 | C25: =Produção!D41 -> 50g/L | D25: =Produção!F41 -> Processamento padrão em série
A26: =Produção!B42 -> 20180511Pa | B26: =Produção!C42 -> P10 | C26: =Produção!D42 -> 50g/L | D26: =Produção!F42 -> Análise de carregamento de grafite expandido
A27: =Produção!B43 -> 20180524Pa | B27: =Produção!C43 -> P50 | C27: =Produção!D43 -> 50g/L | D27: =Produção!F43 -> Teste de reprocessamento do grafite / Abortado
A28: =Produção!B46 -> 20180606Pa | B28: =Produção!C46 -> P50 | C28: =Produção!D46 -> 50g/L | D28: =Produção!F46 -> Teste de reprocessamento do grafite
A29: =Produção!B47 -> 20180612Pa | B29: =Produção!C47 -> P50 | C29: =Produção!D47 -> 50g/L | D29: =Produção!F47 -> Processamento padrão em série
A30: =Produção!B48 -> 20180625Pa | B30: =Produção!C48 -> P100-1 | C30: =Produção!D48 -> 100g/L | D30: =Produção!F48 -> Silverson UHS 175/275 – 6.000rpm
A31: =Produção!B49 -> 20180628Pa | B31: =Produção!C49 -> P100-2 | C31: =Produção!D49 -> 100g/L | D31: =Produção!F49 -> Konmix – 3.550rpm
A32: =Produção!B52 -> 20180709Pa | B32: =Produção!C52 -> P100-2 | C32: =Produção!D52 -> 50g/L | D32: =Produção!F52 -> Konmix – 3.550rpm
A33: =Produção!B53 -> 20180715Pa | B33: =Produção!C53 -> P100-1 | C33: =Produção!D53 -> 50g/L | D33: =Produção!F53 -> Silverson UHS 175/275 – 6.000rpm
A34: =Produção!B54 -> 20180719Pa | B34: =Produção!C54 -> P100-1 | C34: =Produção!D54 -> 50g/L | D34: =Produção!F54 -> Processamento padrão P100 - UHS
A35: =Produção!B57 -> 20180806Pa | B35: =Produção!C57 -> P100 | C35: =Produção!D57 -> 50g/L | D35: =Produção!F57 -> Konmix – 3.550rpm
A36: =Produção!B58 -> 20180809Pa | B36: =Produção!C58 -> P100-1 | C36: =Produção!D58 -> 50g/L | D36: =Produção!F58 -> Silverson UHS 175/275 – 6.000rpm
A37: =Produção!B59 -> 20180812Pa | B37: =Produção!C59 -> P100-1 | C37: =Produção!D59 -> 50g/L | D37: =Produção!F59 -> Silverson UHS 175/275 – 6.000rpm
A38: =Produção!B60 -> 20180814Pa | B38: =Produção!C60 -> P100-1 | C38: =Produção!D60 -> 50g/L | D38: =Produção!F60 -> Silverson UHS 175/275 – 6.000rpm
A39: =Produção!B61 -> 20180828Pa | B39: =Produção!C61 -> P100-2 | C39: =Produção!D61 -> 50g/L | D39: =Produção!F61 -> Konmix – 3.550rpm
A40: =Produção!B62 -> 20180829Pa | B40: =Produção!C62 -> P100-2 | C40: =Produção!D62 -> 50g/L | D40: =Produção!F62 -> Konmix – 3.550rpm
...

Sheet Planilha1
B2: LOTE | E2: SEM. N° | H2: CAMPANHA
B3: Ano | C3: Mês /Dia | D3: c.
B4: 2021 | C4: 1025 | D4: Pa | E4: 43 | F4: P100 | G4: 100 g/L | H4: PC 01 | I4: Konmix – 3.550rpm - tanque inox / NaOH | J4: 100 g/L; 5h; Decnater 300G-75 L/h; Discos
E5: 44
B6: 2021 | C6: 1108 | D6: Pa | E6: 45 | F6: P100 | G6: 50 g/L | I6: Padrão em série(Verso V2 e V4/V3) | J6: 50 g/L; 24 h; Decantação estática, Discos(2x)
B7: 2021 | C7: 1116 | D7: Pa | E7: 46 | F7: P100 | G7: 100g/L | H7: PC 01 | I7: Konmix – 3.550rpm - tanque inox / NaOH | J7: 100 g/L; 5h; Decnater 300G-75 L/h; Discos
B8: 2021 | C8: 1122 | D8: Pa | E8: 47 | F8: P100 | G8: 100g/L | H8: PC 01 | I8: Konmix – 3.550rpm - tanque inox / NaOH | J8: 100 g/L; 5h; Decnater 300G-75 L/h; Discos
B9: 2021 | C9: 1124 | D9: Pa | F9: P100 | G9: 100g/L | H9: PC 01 | I9: Konmix – 3.550rpm - tanque inox / NaOH | J9: 100 g/L; 5h; Decnater 300G-75 L/h; Discos
B10: 2021 | C10: 1129 | D10: Pa | E10: 48 | F10: P100 | G10: 100g/L | H10: PC 01 | I10: Konmix – 3.550rpm - tanque inox / NaOH | J10: 100 g/L; 5h; Decnater 300G-75 L/h; Discos
B11: 2021 | C11: 1201 | D11: Pa | F11: P100 | G11: 100g/L | H11: PC 01 | I11: Konmix – 3.550rpm - tanque inox / NaOH | J11: 100 g/L; 5h; Decnater 300G-75 L/h; Discos
B12: 2021 | C12: 1206 | D12: Pa | E12: 49 | F12: P100 | G12: 100g/L | H12: PC 01 | I12: Konmix – 3.550rpm - tanque inox / NaOH | J12: 100 g/L; 5h; Decnater 300G-75 L/h; Discos
B13: 2021 | C13: 1214 | D13: Pa | E13: 50 | F13: P100 | G13: 100g/L | H13: PC 01 | I13: Konmix – 3.550rpm - tanque inox / NaOH | J13: 100 g/L; 5h; Decnater 300G-75 L/h; Discos
E14: 1
B15: 2022 | C15: 0118Pa | D15: Pa | E15: 3 | F15: P100 | G15: 100g/L | H15: PC 01 | I15: Konmix – 3.550rpm - tanque inox / NaOH | J15: 100 g/L; 5h; Decnater 300G-75 L/h; Discos
E16: 4
E17: 5
B18: 2022 | C18: 0208Pa | D18: Pa | E18: 6 | F18: P100 | G18: 100g/L | H18: Teste | I18: Konmix – 3.550rpm - tanque inox / NaOH-23h | J18: 100 g/L; 23h; Decnater 300G-75 L/h; Discos (Adição de aditivo 1x)
B19: 2022 | C19: 0214Pa | D19: Pa | E19: 7 | F19: P100 | G19: 100g/L | H19: PC 02 | I19: Konmix – 3.550rpm - tanque inox / NaOH | J19: 100 g/L; 5h; Decnater 300G-75 L/h; Processo de Recuperação; Discos; Concentração
B20: 2022 | C20: 0221Pa | D20: Pa | E20: 8 | F20: P100 | G20: 100g/L | H20: PC02 | I20: Konmix – 3.550rpm - tanque inox / NaOH | J20: 100 g/L; 5h; Decnater 300G-75 L/h; Processo de Recuperação; Discos; Concentração
