Workbook

Sheet Ano
A1: Setor | B1: Qtd de lotes | C1: Finalidade do material produzido | G1: Categoria | H1: Qnt lote | I1: Finalidade | J1: Sub-classe | K1: Ano
A2: Entrega | B2: =SUMIF($J$2:$J$40,A2,$H$2:$H$40) -> 7 | C2: =B2*100/$B$9 -> 8.8607595 | G2: P50 | H2: 3 | I2: RHODIA | J2: Entrega | K2: 2017
A3: Flotação | B3: =SUMIF($J$2:$J$40,A3,$H$2:$H$40) -> 14 | C3: =B3*100/$B$9 -> 17.721519 | G3: P50 | H3: 1 | I3: Bancada | J3: Desenvolvimento Bancada | K3: 2017
A4: Desenvolvimento Bancada | B4: =SUMIF($J$2:$J$40,A4,$H$2:$H$40) -> 4 | C4: =B4*100/$B$9 -> 5.0632911 | G4: P25 | H4: 1 | I4: Aumento de carga | J4: Melhoria do processo de conversão | K4: 2017
A5: Testes de Separação | B5: =SUMIF($J$2:$J$40,A5,$H$2:$H$40) -> 6 | C5: =B5*100/$B$9 -> 7.5949367 | G5: P50 | H5: 1 | I5: Decanter | J5: Testes de Separação | K5: 2017
A6: Testes Externos | B6: =SUMIF($J$2:$J$40,A6,$H$2:$H$40) -> 5 | C6: =B6*100/$B$9 -> 6.3291139 | G6: P50 | H6: 4 | I6: KATRINA-Flotação | J6: Flotação | K6: 2017 | L6: 2018
A7: Melhoria do processo de conversão | B7: =SUMIF($J$2:$J$40,A7,$H$2:$H$40) -> 41 | C7: =B7*100/$B$9 -> 51.898734 | G7: P25 | H7: 1 | I7: Teste-IKA | J7: Melhoria do processo de conversão | K7: 2018
A8: Caracterização | B8: =SUMIF($J$2:$J$40,A8,$H$2:$H$40) -> 2 | C8: =B8*100/$B$9 -> 2.5316456 | G8: P5 | H8: 1 | I8: Caracterização | J8: Caracterização | K8: 2018
A9: Total | B9: =SUM(B2:B8) -> 79 | C9: =SUM(C2:C8) -> 100 | G9: P5 | H9: 1 | I9: Teste-Verso | J9: Melhoria do processo de conversão | K9: 2018
G10: P50 | H10: 1 | I10: Desenvolvimento | J10: Desenvolvimento Bancada | K10: 2018
A11: Configuração de linha | B11: Quantidade | C11: Volume (L) | G11: P100 | H11: 4 | I11: IRENE- Start UP | J11: Melhoria do processo de conversão | K11: 2018
A12: P5 | B12: =SUMIF($G$2:$G$40,A12,$H$2:$H$40) -> 2 | C12: =B12*5 -> 10 | G12: P50 | H12: 1 | I12: Teste-cisalhador | J12: Melhoria do processo de conversão | K12: 2018
A13: P25 | B13: =SUMIF($G$2:$G$40,A13,$H$2:$H$40) -> 22 | C13: =B13*25 -> 550 | G13: P50 | H13: 1 | I13: Flotação | J13: Flotação | K13: 2018
A14: P50 | B14: =SUMIF($G$2:$G$40,A14,$H$2:$H$40) -> 17 | C14: =B14*50 -> 850 | G14: P50 | H14: 1 | I14: Teste -grafite exp. | J14: Melhoria do processo de conversão | K14: 2018
A15: P100 | B15: =SUMIF($G$2:$G$40,A15,$H$2:$H$40) -> 38 | C15: =B15*100 -> 3800 | G15: P50 | H15: 1 | I15: Teste-reproc. Grafit | J15: Melhoria do processo de conversão | K15: 2018
G16: P50 | H16: 1 | I16: Leito fluidizado | J16: Melhoria do processo de conversão | K16: 2018
A17: Ano | B17: Qnt lotes | C17: Volume (L) | G17: P100 | H17: 3 | I17: Portifolio CODEMGE | J17: Entrega | K17: 2018
A18: 2017 | B18: =SUMIF($K$2:$K450,A18,$H$2:$H$40) -> 10 | C18: =(SUM(H2:H3,H5:H6)*50)+(H4*25) -> 475 | G18: P100 | H18: 1 | I18: Flotação | J18: Flotação | K18: 2018
A19: 2018 | B19: =SUMIF($K$2:$K451,A19,$H$2:$H$40) -> 29 | C19: =(SUM(H8:H9)*5)+(H7*25)+(SUM(H10,H12:H16)*50)+(SUM(H11,H17:H27)*100) -> 2335 | G19: P100 | H19: 1 | I19: Decanter | J19: Testes de Separação | K19: 2018
A20: 2019 | B20: =SUMIF($K$2:$K452,A20,$H$2:$H$40) -> 12 | C20: =50*(SUM(H29,H31))+(SUM(H28,H30,H32:H36)*100) -> 1100 | G20: P100 | H20: 1 | I20: BM | J20: Melhoria do processo de conversão | K20: 2018
A21: 2020 | B21: =SUMIF($K$2:$K453,A21,$H$2:$H$40) -> 8 | C21: =(SUM(H37:H39)-1)*100 -> 700 | G21: P100 | H21: 3 | I21: Riera | J21: Testes Externos | K21: 2018
A22: 2021 | B22: =SUMIF($K$2:$K454,A22,$H$2:$H$40) -> 49 | C22: =(H40*25)+(SUM(H41:H45,H47:H51)*100)+(H46*50) -> 4150 | G22: P100 | H22: 1 | I22: CSN | J22: Testes Externos | K22: 2018
G23: P100 | H23: 2 | I23: Flotação | J23: Flotação | K23: 2018
G24: P100 | H24: 1 | I24: Decanter | J24: Testes de Separação | K24: 2018
G25: P100 | H25: 1 | I25: SB | J25: Melhoria do processo de conversão | K25: 2018
G26: P100 | H26: 1 | I26: Flotação | J26: Flotação | K26: 2018
G27: P100 | H27: 1 | I27: Dec/Tub/Disc | J27: Testes de Separação | K27: 2018
G28: P100 | H28: 1 | I28: IBA | J28: Testes de Separação | K28: 2019
G29: P50 | H29: 1 | I29: Desenvolvimento | J29: Desenvolvimento Bancada | K29: 2019
G30: P100 | H30: 1 | I30: Pam Membranas | J30: Testes Externos | K30: 2019
G31: P50 | H31: 1 | I31: Desenvolvimento | J31: Desenvolvimento Bancada | K31: 2019
G32: P100 | H32: 1 | I32: Flotação | J32: Flotação | K32: 2019
G33: P100 | H33: 1 | I33: Decanter | J33: Testes de Separação | K33: 2019
G34: P100 | H34: 4 | I34: Flotação | J34: Flotação | K34: 2019
... G38: P100 | H38: 1 | I38: G-Scan | J38: Caracterização | K38: 2020
G39: P100 | H39: 1 | I39: Sally | J39: Melhoria do processo de conversão | K39: 2020 | L39: 2021
G40: P25 | H40: 20 | I40: Otto | J40: Melhoria do processo de conversão | K40: 2021
G41: P100 | H41: 3 | I41: Sally | K41: 2021
G42: P100 | H42: 7 | I42: Ana | K42: 2021
G43: P100 | H43: 5 | I43: Duda | K43: 2021
...

Sheet Mes
A2: CONTROLE DE PRODUÇÃO | K2: Qual a massa de grafeno produzida em um lote de 5L | O2: =0.4*4 -> 1.6
K3: Qual a massa de grafeno produzida em um lote de 10L | O3: =0.4*8 -> 3.2
K4: Qual a massa de grafeno produzida em um lote de 25L | O4: =0.14*15 -> 2.1
A5: Campanhas realizadas no mês de outubro 2017 | H5: 2017 | K5: Qual a massa de grafeno produzida em um lote de 50L | O5: =0.4*35 -> 14
A6: Lote | B6: Piloto | D6: [ ] | E6: Campanha | F6: Descrição | G6: Objetivo | K6: Qual a massa de grafeno produzida em um lote de 100L (2018) | O6: =1.5*80 -> 120
A7: 20171003Pa | B7: P50 | C7: 50 | D7: 50g/L | E7: RHODIA | F7: Processamento padrão em série | G7: Lote para testes de aplicação em potencial cliente : RHODIA | K7: Qual a massa de grafeno produzida em um lote de 100L (2019) | O7: =0.55*80 -> 44
A8: 20171010Pa | B8: P50 | C8: 50 | D8: 50g/L | E8: RHODIA | F8: Processamento padrão em série | G8: Lote para testes de aplicação em potencial cliente : RHODIA | K8: Qual a massa de grafeno produzida em um lote de 100L (2021) | O8: =0.55*80 -> 44
A9: 20171013Pa | B9: P50 | C9: 50 | D9: 50g/L | E9: RHODIA | F9: Processamento padrão em série | G9: Lote para testes de aplicação em potencial cliente : RHODIA
A10: Campanhas realizadas no mês de novembro 2017
A11: Lote | B11: Piloto | D11: [ ] | E11: Campanha | F11: Descrição | G11: Objetivo | L11: 43009 | M11: 43040 | N11: 43070 | O11: 43101 | P11: 43132 | Q11: 43160 | R11: 43191 | S11: 43221 | T11: 43252 | U11: 43282 | V11: 43313 | W11: 43344 | X11: 43374 | Y11: 43405 | Z11: 43435 | AA11: 43466 | AB11: 43497 | AC11: 43525 | AD11: 43556 | AE11: 43586 | AF11: 43617 | AG11: 43647 | AH11: 43678 | AI11: 43709 | AJ11: 43739 | AK11: 43770 | AL11: 43800 | AM11: 43831 | AN11: 43862 | AO11: 43891 | AP11: 43922 | AQ11: 43952 | AR11: 43983 | AS11: 44013 | AT11: 44044 | AU11: 44075 | AV11: 44105 | AW11: 44136 | AX11: 44166 | AY11: 44197 | AZ11: 44228 | BA11: 44256 | BB11: 44287 | BC11: 44317 | BD11: 44348 | BE11: 44378 | BF11: 44409 | BG11: 44440 | BH11: 44470 | BI11: 44501 | BJ11: 44531 | BK11: 44562 | BL11: 44593
A12: 20171112Pa | B12: P50 | C12: 50 | D12: 50g/L | F12: Processamento padrão em série | G12: Lote para testes de otimização de centrifugação em bancada ( Frente Bancada ) | K12: Quantidade de lotes produzidos | L12: 3 | M12: 3 | N12: 2 | O12: 4 | P12: 1 | Q12: 3 | R12: 4 | S12: 4 | T12: 4 | U12: 3 | V12: 6 | W12: 4 | X12: 2 | Y12: 1 | Z12: 0 | AA12: 2 | AB12: 1 | AC12: 1 | AD12: 0 | AE12: 4 | AF12: 5 | AG12: 0 | AH12: 0 | AI12: 0 | AJ12: 0 | AK12: 0 | AL12: 0 | AM12: 0 | AN12: 0 | AO12: 1 | AP12: 0 | AQ12: 0 | AR12: 0 | AS12: 0 | AT12: 0 | AU12: 4 | AV12: 2 | AW12: 1 | AX12: 0 | AY12: 3 | AZ12: 8 | BA12: 5 | BB12: 0 | BC12: 8 | BD12: 7 | BE12: 6 | BF12: 5 | BG12: 5 | BH12: 2 | BI12: 5 | BJ12: 3 | BK12: 1 | BL12: 3
A13: 20171120Pa | B13: P25 | C13: 25 | D13: 100g/L | F13: Teste operacional com aumento da [ ] = 100g/L | G13: Avaliação da capacidade de processamento do equipamento silverson VERSO com aumento da concentração inicial de grafite para 100g/L | K13: Somatório lotes produzidos | L13: =L12 -> 3 | M13: =SUM(L12:M12) -> 6 | N13: =SUM(L12:N12) -> 8 | O13: =SUM(L12:O12) -> 12 | P13: =SUM(L12:P12) -> 13 | Q13: =SUM(L12:Q12) -> 16 | R13: =SUM(L12:R12) -> 20 | S13: =SUM(L12:S12) -> 24 | T13: =SUM(L12:T12) -> 28 | U13: =SUM(L12:U12) -> 31 | V13: =SUM(L12:V12) -> 37 | W13: =SUM(L12:W12) -> 41 | X13: =SUM(L12:X12) -> 43 | Y13: =SUM(L12:Y12) -> 44 | Z13: =SUM(L12:Z12) -> 44 | AA13: =SUM(L12:AA12) -> 46 | AB13: =SUM(L12:AB12) -> 47 | AC13: =SUM(L12:AC12) -> 48 | AD13: =SUM(L12:AD12) -> 48 | AE13: =SUM(L12:AE12) -> 52 | AF13: =SUM(L12:AF12) -> 57 | AG13: =SUM(L12:AG12) -> 57 | AH13: =SUM(L12:AH12) -> 57 | AI13: =SUM(L12:AI12) -> 57 | AJ13: =SUM(L12:AJ12) -> 57 | AK13: =SUM(L12:AK12) -> 57 | AL13: =SUM(L12:AL12) -> 57 | AM13: =SUM(L12:AM12) -> 57 | AN13: =SUM(L12:AN12) -> 57 | AO13: =SUM(L12:AO12) -> 58 | AP13: =SUM(L12:AP12) -> 58 | AQ13: =SUM(L12:AQ12) -> 58 | AR13: =SUM(L12:AR12) -> 58 | AS13: =SUM(L12:AS12) -> 58 | AT13: =SUM(L12:AT12) -> 58 | AU13: =SUM(L12:AU12) -> 62 | AV13: =SUM(L12:AV12) -> 64 | AW13: =SUM(L12:AW12) -> 65 | AX13: =SUM(L12:AX12) -> 65 | AY13: =SUM(L12:AY12) -> 68 | AZ13: =SUM(L12:AZ12) -> 76 | BA13: =SUM(L12:BA12) -> 81 | BB13: =SUM(L12:BB12) -> 81 | BC13: =SUM(L12:BC12) -> 89 | BD13: =SUM(L12:BD12) -> 96 | BE13: =SUM(L12:BE12) -> 102 | BF13: =SUM(L12:BF12) -> 107 | BG13: =SUM(L12:BG12) -> 112 | BH13: =SUM(L12:BH12) -> 114 | BI13: =SUM(L12:BI12) -> 119 | BJ13: =SUM(L12:BJ12) -> 122 | BK13: =SUM(L12:BK12) -> 123 | BL13: =SUM(L12:BL12) -> 126
A14: 20171124Pa | B14: P50 | C14: 50 | D14: 50g/L | F14: Startup Centrifuga Decanter | G14: Testes conceito com equipamendo alugado ( OMEGALINE ) 2000 L/h | K14: Volume (L) | L14: 150 | M14: 125 | N14: 100 | O14: 175 | P14: 5 | Q14: 155 | R14: 400 | S14: 160 | T14: 300 | U14: 300 | V14: 600 | W14: 400 | X14: 100 | Y14: 100 | Z14: 0 | AA14: 150 | AB14: 100 | AC14: 50 | AD14: 0 | AE14: 400 | AF14: 400 | AG14: 0 | AH14: 0 | AI14: 0 | AJ14: 0 | AK14: 0 | AL14: 0 | AM14: 0 | AN14: 0 | AO14: 100 | AP14: 0 | AQ14: 0 | AR14: 0 | AS14: 0 | AT14: 0 | AU14: 400 | AV14: 200 | AW14: 100 | AX14: 0 | AY14: 150 | AZ14: 200 | BA14: 200 | BB14: 0 | BC14: 500 | BD14: 400 | BE14: 450 | BF14: 500 | BG14: 500 | BH14: 200 | BI14: 500 | BJ14: 300 | BK14: 100 | BL14: 300
A15: Campanhas realizadas no mês de dezembro 2017 | K15: Somatório Volume (L) | L15: =L14 -> 150 | M15: =SUM(L14:M14) -> 275 | N15: =SUM(L14:N14) -> 375 | O15: =SUM(L14:O14) -> 550 | P15: =SUM(L14:P14) -> 555 | Q15: =SUM(L14:Q14) -> 710 | R15: =SUM(L14:R14) -> 1110 | S15: =SUM(L14:S14) -> 1270 | T15: =SUM(L14:T14) -> 1570 | U15: =SUM(L14:U14) -> 1870 | V15: =SUM(L14:V14) -> 2470 | W15: =SUM(L14:W14) -> 2870 | X15: =SUM(L14:X14) -> 2970 | Y15: =SUM(L14:Y14) -> 3070 | Z15: =SUM(L14:Z14) -> 3070 | AA15: =SUM(L14:AA14) -> 3220 | AB15: =SUM(L14:AB14) -> 3320 | AC15: =SUM(L14:AC14) -> 3370 | AD15: =SUM(L14:AD14) -> 3370 | AE15: =SUM(L14:AE14) -> 3770 | AF15: =SUM(L14:AF14) -> 4170 | AG15: =SUM(L14:AG14) -> 4170 | AH15: =SUM(L14:AH14) -> 4170 | AI15: =SUM(L14:AI14) -> 4170 | AJ15: =SUM(L14:AJ14) -> 4170 | AK15: =SUM(L14:AK14) -> 4170 | AL15: =SUM(L14:AL14) -> 4170 | AM15: =SUM(L14:AM14) -> 4170 | AN15: =SUM(L14:AN14) -> 4170 | AO15: =SUM(L14:AO14) -> 4270 | AP15: =SUM(L14:AP14) -> 4270 | AQ15: =SUM(L14:AQ14) -> 4270 | AR15: =SUM(L14:AR14) -> 4270 | AS15: =SUM(L14:AS14) -> 4270 | AT15: =SUM(L14:AT14) -> 4270 | AU15: =SUM(L14:AU14) -> 4670 | AV15: =SUM(L14:AV14) -> 4870 | AW15: =SUM(L14:AW14) -> 4970 | AX15: =SUM(L14:AX14) -> 4970 | AY15: =SUM(L14:AY14) -> 5120 | AZ15: =SUM(L14:AZ14) -> 5320 | BA15: =SUM(L14:BA14) -> 5520 | BB15: =SUM(L14:BB14) -> 5520 | BC15: =SUM(L14:BC14) -> 6020 | BD15: =SUM(L14:BD14) -> 6420 | BE15: =SUM(L14:BE14) -> 6870 | BF15: =SUM(L14:BF14) -> 7370 | BG15: =SUM(L14:BG14) -> 7870 | BH15: =SUM(L14:BH14) -> 8070 | BI15: =SUM(L14:BI14) -> 8570 | BJ15: =SUM(L14:BJ14) -> 8870 | BK15: =SUM(L14:BK14) -> 8970 | BL15: =SUM(L14:BL14) -> 9270
A16: Lote | B16: Piloto | D16: [ ] | E16: Campanha | F16: Descrição | G16: Objetivo | K16: Massa (g) | L16: =L12*O5 -> 42 | M16: =2*O5+O4 -> 30.1 | N16: =N12*O5 -> 28 | O16: =3*O5+O4 -> 44.1 | P16: =O2 -> 1.6 | Q16: =O2+O5+O6 -> 135.6 | R16: =R12*O6 -> 480 | S16: =3*O5+O3 -> 45.2 | T16: =2*O5+2*O6 -> 268 | U16: =U12*O6 -> 360 | V16: =V12*O6 -> 720 | W16: =W12*O6 -> 480 | X16: =X12*O5 -> 28 | Y16: =Y12*O6 -> 120 | Z16: 0 | AA16: =O5+O6 -> 134 | AB16: =O6 -> 120 | AC16: =O5 -> 14 | AD16: 0 | AE16: =AE12*O6 -> 480 | AF16: =AF12*O7 -> 220 | AG16: 0 | AH16: 0 | AI16: 0 | AJ16: 0 | AK16: 0 | AL16: 0 | AM16: 0 | AN16: 0 | AO16: =AO12*O7 -> 44 | AP16: 0 | AQ16: 0 | AR16: 0 | AS16: 0 | AT16: 0 | AU16: =AU12*O7 -> 176 | AV16: =AV12*O7 -> 88 | AW16: =AW12*O7 -> 44 | AX16: 0 | AY16: =2*O4+O7 -> 48.2 | AZ16: =AZ12*O4 -> 16.8 | BA16: =4*O4+O7 -> 52.4 | BB16: 0 | BC16: =(4*O4)+(4*O7) -> 184.4 | BD16: =4*O4+3*O7 -> 140.4 | BE16: =2*O4+4*O8 -> 180.2 | BF16: =BF12*O8 -> 220 | BG16: =BG12*O8 -> 220 | BH16: =BH12*O8 -> 88 | BI16: =BI12*O8 -> 220 | BJ16: =BJ12*O8 -> 132 | BK16: =BK12*O8 -> 44 | BL16: =BL12*O8 -> 132
A17: 20171227Pa | B17: P50 | C17: 50 | D17: 50g/L | E17: KATRINA | F17: Processamento padrão em série | G17: Lote padrão P50 em série para testes de flotação em coluna | K17: Grafeno produzido acumulado (g) | L17: =L16 -> 42 | M17: =SUM(L16:M16) -> 72.1 | N17: =SUM(L16:N16) -> 100.1 | O17: =SUM(L16:O16) -> 144.2 | P17: =SUM(L16:P16) -> 145.8 | Q17: =SUM(L16:Q16) -> 281.4 | R17: =SUM(L16:R16) -> 761.4 | S17: =SUM(L16:S16) -> 806.6 | T17: =SUM(L16:T16) -> 1074.6 | U17: =SUM(L16:U16) -> 1434.6 | V17: =SUM(L16:V16) -> 2154.6 | W17: =SUM(L16:W16) -> 2634.6 | X17: =SUM(L16:X16) -> 2662.6 | Y17: =SUM(L16:Y16) -> 2782.6 | Z17: =SUM(L16:Z16) -> 2782.6 | AA17: =SUM(L16:AA16) -> 2916.6 | AB17: =SUM(L16:AB16) -> 3036.6 | AC17: =SUM(L16:AC16) -> 3050.6 | AD17: =SUM(L16:AD16) -> 3050.6 | AE17: =SUM(L16:AE16) -> 3530.6 | AF17: =SUM(L16:AF16) -> 3750.6 | AG17: =SUM(L16:AG16) -> 3750.6 | AH17: =SUM(L16:AH16) -> 3750.6 | AI17: =SUM(L16:AI16) -> 3750.6 | AJ17: =SUM(L16:AJ16) -> 3750.6 | AK17: =SUM(L16:AK16) -> 3750.6 | AL17: =SUM(L16:AL16) -> 3750.6 | AM17: =SUM(L16:AM16) -> 3750.6 | AN17: =SUM(L16:AN16) -> 3750.6 | AO17: =SUM(L16:AO16) -> 3794.6 | AP17: =SUM(L16:AP16) -> 3794.6 | AQ17: =SUM(L16:AQ16) -> 3794.6 | AR17: =SUM(L16:AR16) -> 3794.6 | AS17: =SUM(L16:AS16) -> 3794.6 | AT17: =SUM(L16:AT16) -> 3794.6 | AU17: =SUM(L16:AU16) -> 3970.6 | AV17: =SUM(L16:AV16) -> 4058.6 | AW17: =SUM(L16:AW16) -> 4102.6 | AX17: =SUM(L16:AX16) -> 4102.6 | AY17: =SUM(L16:AY16) -> 4150.8 | AZ17: =SUM(L16:AZ16) -> 4167.6 | BA17: =SUM(L16:BA16) -> 4220 | BB17: =SUM(L16:BB16) -> 4220 | BC17: =SUM(L16:BC16) -> 4404.4 | BD17: =SUM(L16:BD16) -> 4544.8 | BE17: =SUM(L16:BE16) -> 4725 | BF17: =SUM(L16:BF16) -> 4945 | BG17: =SUM(L16:BG16) -> 5165 | BH17: =SUM(L16:BH16) -> 5253 | BI17: =SUM(L16:BI16) -> 5473 | BJ17: =SUM(L16:BJ16) -> 5605 | BK17: =SUM(L16:BK16) -> 5649 | BL17: =SUM(L16:BL16) -> 5781
A18: 20171228Pa | B18: P50 | C18: 50 | D18: 50g/L | E18: KATRINA | F18: Processamento padrão em série | G18: Lote padrão P50 em série para testes de flotação em coluna | K18: Grafeno de poucas camadas acumulado (kg) | L18: =L17/1000 -> 0.042 | M18: =M17/1000 -> 0.0721 | N18: =N17/1000 -> 0.1001 | O18: =O17/1000 -> 0.1442 | P18: =P17/1000 -> 0.1458 | Q18: =Q17/1000 -> 0.2814 | R18: =R17/1000 -> 0.7614 | S18: =S17/1000 -> 0.8066 | ... BL18: =BL17/1000 -> 5.781
A19: Campanhas realizadas no mês de janeiro 2018 | H19: 2018 | K19: Volume processado (L)/ Grafeno produzido (kg) | L19: =L15/L18 -> 3571.4286 | M19: =M15/M18 -> 3814.147 | N19: =N15/N18 -> 3746.2537 | O19: =O15/O18 -> 3814.147 | P19: =P15/P18 -> 3806.5844 | Q19: =Q15/Q18 -> 2523.0988 | R19: =R15/R18 -> 1457.8408 | S19: =S15/S18 -> 1574.5103 | ... BL19: =BL15/BL18 -> 1603.5288
A20: Lote | B20: Piloto | D20: [ ] | E20: Campanha | F20: Descrição | G20: Objetivo
A21: 20180102Pa | B21: P50 | C21: 50 | D21: 50g/L | E21: KATRINA | F21: Processamento padrão em série | G21: Lote padrão P50 em série para testes de flotação em coluna | L21: =L13*20 -> 60 | M21: =M13*50 -> 300 | N21: =N13*50 -> 400 | O21: =O13*50 -> 600 | P21: =P13*50 -> 650 | Q21: =Q13*50 -> 800 | R21: =R13*50 -> 1000 | S21: =S13*50 -> 1200 | T21: =T13*50 -> 1400 | ... BK21: =BK13*50 -> 6150
A22: 20180103Pa | B22: P50 | C22: 50 | D22: 50g/L | E22: KATRINA | F22: Processamento padrão em série | G22: Lote padrão P50 em série para testes de flotação em coluna
A23: 20180108Pa | B23: P50 | C23: 50 | D23: 50g/L | E23: KATRINA | F23: Homogeinização da campanha KATRINA | G23: Homogeinização de 200L gerados na campanha KATRINA para testes de flotação em coluna / Portifólio 01
A25: 20180130Pa | B25: P25 | C25: 25 | D25: 100g/L
A26: Campanhas realizadas no mês de fevereiro 2018 | F26: Teste piloto IKA | G26: Avaliar curva de rendimento com equipamento alugado da IKA
A27: Lote | B27: Piloto | D27: [ ] | E27: Campanha
A28: 20180220Pa | B28: P5 | C28: 5 | D28: 50g/L | F28: Descrição | G28: Objetivo
A29: Campanhas realizadas no mês de março 2018 | F29: Avaliação da reprodutibilidade | G29: Avaliar reprodutibilidade na escala piloto P5 até 5 litros ( Frente Caracterização )
A30: Lote | B30: Piloto | D30: [ ] | E30: Campanha
A31: 20180312Pa | B31: P5 | C31: 5 | D31: 50g/L | F31: Descrição | G31: Objetivo
A32: 20180313Pa | B32: P50 | C32: 50 | D32: 50g/L | F32: Teste de selo mecânico nacional - Silverson Verso | G32: Busca de fornecedor alternativo para selos mecânicos para o equipamento silverson VERSO
A33: 20180321Pa | B33: P100 | C33: 100 | D33: 50g/L | F33: Processamento padrão em série | G33: Para testes de flotação em bancada
A34: Campanhas realizadas no mês de abril 2018 | F34: Startup Konmix - 3.550rpm | G34: Startup Konmix para adequação das condições operações
A35: Lote | B35: Piloto | D35: [ ] | E35: Campanha
A36: 20180402Pa | B36: P100 | C36: 100 | D36: 50g/L | F36: Descrição | G36: Objetivo
A37: 20180417Pa | B37: P100 | C37: 100 | D37: 50g/L | E37: IRENE | F37: Startup Silverson UHS 175/275 – 3.600rpm | G37: Startup Silverson para adequação das condições operações
A38: 20180417Pb | B38: P100 | C38: 100 | D38: 50g/L | E38: IRENE | F38: Silverson UHS 175/275 – 3.600rpm | G38: Curva de rendimento do Silverson UHS 175/275 - 3.600rpm
A39: 20180424Pa | B39: P100 | C39: 100 | D39: 50g/L | F39: Konmix – 3.550rpm | G39: Curva de rendimento do Konmix- 3.550rpm
A40: Campanhas realizadas no mês de maio 2018 | F40: Silverson UHS 175/275 – 6.000rpm | G40: Curva de rendimento do Silverson UHS 175/275 - 6.000rpm
A41: Lote | B41: Piloto | D41: [ ]
A42: 20180502Pa | B42: P50 | C42: 50 | D42: 50g/L | F42: Descrição | G42: Objetivo
...

Sheet 2021
A2: CONTROLE DE PRODUÇÃO | K2: Qual a massa de grafeno produzida em um lote de 5L | O2: =0.4*4 -> 1.6
K3: Qual a massa de grafeno produzida em um lote de 10L | O3: =0.4*8 -> 3.2
K4: Qual a massa de grafeno produzida em um lote de 25L | O4: =0.14*15 -> 2.1
A5: Campanhas realizadas no mês de outubro 2017 | H5: 2017 | K5: Qual a massa de grafeno produzida em um lote de 50L | O5: =0.4*35 -> 14
A6: Lote | B6: Piloto | D6: [ ] | E6: Campanha | F6: Descrição | G6: Objetivo | K6: Qual a massa de grafeno produzida em um lote de 100L (2018) | O6: =1.5*80 -> 120
A7: 20171003Pa | B7: P50 | C7: 50 | D7: 50g/L | E7: RHODIA | F7: Processamento padrão em série | G7: Lote para testes de aplicação em potencial cliente : RHODIA | K7: Qual a massa de grafeno produzida em um lote de 100L (2019) | O7: =0.55*80 -> 44
A8: 20171010Pa | B8: P50 | C8: 50 | D8: 50g/L | E8: RHODIA | F8: Processamento padrão em série | G8: Lote para testes de aplicação em potencial cliente : RHODIA | K8: Qual a massa de grafeno produzida em um lote de 100L (2021) | O8: =0.55*80 -> 44
A9: 20171013Pa | B9: P50 | C9: 50 | D9: 50g/L | E9: RHODIA | F9: Processamento padrão em série | G9: Lote para testes de aplicação em potencial cliente : RHODIA
A10: Campanhas realizadas no mês de novembro 2017
A11: Lote | B11: Piloto | D11: [ ] | E11: Campanha | F11: Descrição | G11: Objetivo | L11: 44197 | M11: 44228 | N11: 44256 | O11: 44287 | P11: 44317 | Q11: 44348 | R11: 44378 | S11: 44409 | T11: 44440 | U11: 44470 | V11: 44501 | W11: 44531 | X11: 44562 | Y11: 44593
A12: 20171112Pa | B12: P50 | C12: 50 | D12: 50g/L | F12: Processamento padrão em série | G12: Lote para testes de otimização de centrifugação em bancada ( Frente Bancada ) | K12: Quantidade de lotes produzidos | L12: 3 | M12: 8 | N12: 5 | O12: 0 | P12: 8 | Q12: 7 | R12: 6 | S12: 5 | T12: 5 | U12: 2 | V12: 5 | W12: 3 | X12: 1 | Y12: 3
A13: 20171120Pa | B13: P25 | C13: 25 | D13: 100g/L | F13: Teste operacional com aumento da [ ] = 100g/L | G13: Avaliação da capacidade de processamento do equipamento silverson VERSO com aumento da concentração inicial de grafite para 100g/L | K13: Somatório lotes produzidos | L13: =SUM(L12:L12) -> 3 | M13: =SUM(L12:M12) -> 11 | N13: =SUM(L12:N12) -> 16 | O13: =SUM(L12:O12) -> 16 | P13: =SUM(L12:P12) -> 24 | Q13: =SUM(L12:Q12) -> 31 | R13: =SUM(L12:R12) -> 37 | S13: =SUM(L12:S12) -> 42 | T13: =SUM(L12:T12) -> 47 | U13: =SUM(L12:U12) -> 49 | V13: =SUM(L12:V12) -> 54 | W13: =SUM(L12:W12) -> 57 | X13: =SUM(L12:X12) -> 58 | Y13: =SUM(L12:Y12) -> 61
A14: 20171124Pa | B14: P50 | C14: 50 | D14: 50g/L | F14: Startup Centrifuga Decanter | G14: Testes conceito com equipamendo alugado ( OMEGALINE ) 2000 L/h | K14: Volume (L) | L14: 150 | M14: 200 | N14: 200 | O14: 0 | P14: 500 | Q14: 400 | R14: 450 | S14: 500 | T14: 500 | U14: 200 | V14: 500 | W14: 300 | X14: 100 | Y14: 300
A15: Campanhas realizadas no mês de dezembro 2017 | K15: Somatório Volume (L) | L15: =SUM(L14:L14) -> 150 | M15: =SUM(L14:M14) -> 350 | N15: =SUM(L14:N14) -> 550 | O15: =SUM(L14:O14) -> 550 | P15: =SUM(L14:P14) -> 1050 | Q15: =SUM(L14:Q14) -> 1450 | R15: =SUM(L14:R14) -> 1900 | S15: =SUM(L14:S14) -> 2400 | T15: =SUM(L14:T14) -> 2900 | U15: =SUM(L14:U14) -> 3100 | V15: =SUM(L14:V14) -> 3600 | W15: =SUM(L14:W14) -> 3900 | X15: =SUM(L14:X14) -> 4000 | Y15: =SUM(L14:Y14) -> 4300
A16: Lote | B16: Piloto | D16: [ ] | E16: Campanha | F16: Descrição | G16: Objetivo | K16: Massa (g) | L16: =2*O4+O7 -> 48.2 | M16: =M12*O4 -> 16.8 | N16: =4*O4+O7 -> 52.4 | O16: 0 | P16: =(4*O4)+(4*O7) -> 184.4 | Q16: =4*O4+3*O7 -> 140.4 | R16: =2*O4+4*O8 -> 180.2 | S16: =S12*O8 -> 220 | T16: =T12*O8 -> 220 | U16: =U12*O8 -> 88 | V16: =V12*O8 -> 220 | W16: =W12*O8 -> 132 | X16: =X12*O8 -> 44 | Y16: =Y12*O8 -> 132
A17: 20171227Pa | B17: P50 | C17: 50 | D17: 50g/L | E17: KATRINA | F17: Processamento padrão em série | G17: Lote padrão P50 em série para testes de flotação em coluna | K17: Grafeno produzido acumulado (g) | L17: =SUM(L16:L16) -> 48.2 | M17: =SUM(L16:M16) -> 65 | N17: =SUM(L16:N16) -> 117.4 | O17: =SUM(L16:O16) -> 117.4 | P17: =SUM(L16:P16) -> 301.8 | Q17: =SUM(L16:Q16) -> 442.2 | R17: =SUM(L16:R16) -> 622.4 | S17: =SUM(L16:S16) -> 842.4 | T17: =SUM(L16:T16) -> 1062.4 | U17: =SUM(L16:U16) -> 1150.4 | V17: =SUM(L16:V16) -> 1370.4 | W17: =SUM(L16:W16) -> 1502.4 | X17: =SUM(L16:X16) -> 1546.4 | Y17: =SUM(L16:Y16) -> 1678.4
A18: 20171228Pa | B18: P50 | C18: 50 | D18: 50g/L | E18: KATRINA | F18: Processamento padrão em série | G18: Lote padrão P50 em série para testes de flotação em coluna | K18: Grafeno de poucas camadas acumulado (kg) | L18: =L17/1000 -> 0.0482 | M18: =M17/1000 -> 0.065 | N18: =N17/1000 -> 0.1174 | O18: =O17/1000 -> 0.1174 | P18: =P17/1000 -> 0.3018 | Q18: =Q17/1000 -> 0.4422 | R18: =R17/1000 -> 0.6224 | S18: =S17/1000 -> 0.8424 | ... Y18: =Y17/1000 -> 1.6784
K19: Nanoplaca de grafeno | L19: 0.286 | N19: 0.402 | P19: 0.239 | Q19: 0.816 | R19: 0.984 | S19: 1.408 | T19: 1.542 | U19: 0.583 | V19: 1.486 | W19: 1.076 | X19: 0.336 | Y19: 0.677
K20: Acumulado nanoplaca de grafeno | L20: =L19 -> 0.286 | M20: =SUM(L19:M19) -> 0.286 | N20: =SUM(L19:N19) -> 0.688 | O20: =SUM(L19:O19) -> 0.688 | P20: =SUM(L19:P19) -> 0.927 | Q20: =SUM(L19:Q19) -> 1.743 | R20: =SUM(L19:R19) -> 2.727 | S20: =SUM(L19:S19) -> 4.135 | T20: =SUM(L19:T19) -> 5.677 | U20: =SUM(L19:U19) -> 6.26 | V20: =SUM(L19:V19) -> 7.746 | W20: =SUM(L19:W19) -> 8.822 | X20: =SUM(L19:X19) -> 9.158 | Y20: =SUM(L19:Y19) -> 9.835
K21: Acumulado grafeno (kg) | L21: =L20+L18 -> 0.3342 | M21: =M20+M18 -> 0.351 | N21: =N20+N18 -> 0.8054 | O21: =O20+O18 -> 0.8054 | P21: =P20+P18 -> 1.2288 | Q21: =Q20+Q18 -> 2.1852 | R21: =R20+R18 -> 3.3494 | S21: =S20+S18 -> 4.9774 | ... Y21: =Y20+Y18 -> 11.5134
A22: Campanhas realizadas no mês de janeiro 2018 | H22: 2018 | K22: Volume processado (L)/ Grafeno produzido (kg) | L22: =L15/L18 -> 3112.0332 | M22: =M15/M18 -> 5384.6154 | N22: =N15/N18 -> 4684.8382 | O22: =O15/O18 -> 4684.8382 | P22: =P15/P18 -> 3479.1252 | Q22: =Q15/Q18 -> 3279.0592 | R22: =R15/R18 -> 3052.6992 | S22: =S15/S18 -> 2849.0028 | ... Y22: =Y15/Y18 -> 2561.9638
A23: Lote | B23: Piloto | D23: [ ] | E23: Campanha | F23: Descrição | G23: Objetivo
A24: 20180102Pa | B24: P50 | C24: 50 | D24: 50g/L | E24: KATRINA | F24: Processamento padrão em série | G24: Lote padrão P50 em série para testes de flotação em coluna | L24: =L13*50 -> 150 | M24: =M13*50 -> 550 | N24: =N13*50 -> 800 | O24: =O13*50 -> 800 | P24: =P13*50 -> 1200 | Q24: =Q13*50 -> 1550 | R24: =R13*50 -> 1850 | S24: =S13*50 -> 2100 | ... X24: =X13*50 -> 2900
A25: 20180103Pa | B25: P50 | C25: 50 | D25: 50g/L | E25: KATRINA | F25: Processamento padrão em série | G25: Lote padrão P50 em série para testes de flotação em coluna
A26: 20180108Pa | B26: P50 | C26: 50 | D26: 50g/L | E26: KATRINA | F26: Homogeinização da campanha KATRINA | G26: Homogeinização de 200L gerados na campanha KATRINA para testes de flotação em coluna / Portifólio 01
A28: 20180130Pa | B28: P25 | C28: 25 | D28: 100g/L
A29: Campanhas realizadas no mês de fevereiro 2018 | F29: Teste piloto IKA | G29: Avaliar curva de rendimento com equipamento alugado da IKA
A30: Lote | B30: Piloto | D30: [ ] | E30: Campanha
A31: 20180220Pa | B31: P5 | C31: 5 | D31: 50g/L | F31: Descrição | G31: Objetivo
A32: Campanhas realizadas no mês de março 2018 | F32: Avaliação da reprodutibilidade | G32: Avaliar reprodutibilidade na escala piloto P5 até 5 litros ( Frente Caracterização )
A33: Lote | B33: Piloto | D33: [ ] | E33: Campanha
A34: 20180312Pa | B34: P5 | C34: 5 | D34: 50g/L | F34: Descrição | G34: Objetivo
A35: 20180313Pa | B35: P50 | C35: 50 | D35: 50g/L | F35: Teste de selo mecânico nacional - Silverson Verso | G35: Busca de fornecedor alternativo para selos mecânicos para o equipamento silverson VERSO
A36: 20180321Pa | B36: P100 | C36: 100 | D36: 50g/L | F36: Processamento padrão em série | G36: Para testes de flotação em bancada
A37: Campanhas realizadas no mês de abril 2018 | F37: Startup Konmix - 3.550rpm | G37: Startup Konmix para adequação das condições operações
A38: Lote | B38: Piloto | D38: [ ] | E38: Campanha
A39: 20180402Pa | B39: P100 | C39: 100 | D39: 50g/L | F39: Descrição | G39: Objetivo
A40: 20180417Pa | B40: P100 | C40: 100 | D40: 50g/L | E40: IRENE | F40: Startup Silverson UHS 175/275 – 3.600rpm | G40: Startup Silverson para adequação das condições operações
A41: 20180417Pb | B41: P100 | C41: 100 | D41: 50g/L | E41: IRENE | F41: Silverson UHS 175/275 – 3.600rpm | G41: Curva de rendimento do Silverson UHS 175/275 - 3.600rpm
A42: 20180424Pa | B42: P100 | C42: 100 | D42: 50g/L | F42: Konmix – 3.550rpm | G42: Curva de rendimento do Konmix- 3.550rpm
...

Sheet Planilha1
B1: 2017 | D1: 2018 | F1: 2019 | H1: 2020 | J1: 2021 | L1: 2022
B2: Lotes | C2: Volume | D2: Lotes | E2: Volume | F2: Lotes | G2: Volume | H2: Lotes | I2: Volume | J2: Lotes | K2: Volume | L2: Lotes | M2: Volume
A3: Janeiro | D3: =COUNTA(Mes!B21:B25) -> 4 | E3: =SUM(Mes!C21:C25) -> 175 | F3: =COUNTA(Mes!B80:B81) -> 2 | G3: =SUM(Mes!C80:C81) -> 150 | H3: 0 | I3: 0 | J3: =COUNTA(Mes!B110:B112) -> 3 | K3: =SUM(Mes!C110:C112) -> 150 | L3: =COUNTA(Mes!B178) -> 1 | M3: =SUM(Mes!C178) -> 100
A4: Fevereiro | D4: =COUNTA(Mes!B28) -> 1 | E4: =SUM(Mes!C28) -> 5 | F4: =COUNTA(Mes!B83) -> 1 | G4: =SUM(Mes!C83) -> 100 | H4: 0 | I4: 0 | J4: =COUNTA(Mes!B114:B121) -> 8 | K4: =SUM(Mes!C114:C121) -> 200 | L4: 3 | M4: 300
A5: Março | D5: =COUNTA(Mes!B31:B33) -> 3 | E5: =SUM(Mes!C31:C33) -> 155 | F5: =COUNTA(Mes!B85) -> 1 | G5: =SUM(Mes!C85) -> 50 | H5: =COUNTA(Mes!B98) -> 1 | I5: =SUM(Mes!C98) -> 100 | J5: =COUNTA(Mes!B123:B127) -> 5 | K5: =SUM(Mes!C123:C127) -> 200
A6: Abril | D6: =COUNTA(Mes!B36:B39) -> 4 | E6: =SUM(Mes!C36:C39) -> 400 | F6: 0 | G6: 0 | H6: 0 | I6: 0 | J6: 0 | K6: 0
A7: Maio | D7: =COUNTA(Mes!B42:B45) -> 4 | E7: =SUM(Mes!C42:C45) -> 160 | F7: =COUNTA(Mes!B87:B90) -> 4 | G7: =SUM(Mes!C87:C90) -> 400 | H7: 0 | I7: 0 | J7: =COUNTA(Mes!B129:B136) -> 8 | K7: =SUM(Mes!C129:C136) -> 500
A8: Junho | D8: =COUNTA(Mes!B48:B51) -> 4 | E8: =SUM(Mes!C48:C51) -> 300 | F8: =COUNTA(Mes!B92:B96) -> 4 | G8: =SUM(Mes!C92:C96) -> 400 | H8: 0 | I8: 0 | J8: =COUNTA(Mes!B138:B144) -> 7 | K8: =SUM(Mes!C138:C144) -> 400
A9: Julho | D9: =COUNTA(Mes!B54:B56) -> 3 | E9: =SUM(Mes!C54:C56) -> 300 | F9: 0 | G9: 0 | H9: 0 | I9: 0 | J9: =COUNTA(Mes!B146:B151) -> 6 | K9: =SUM(Mes!C146:C151) -> 450
A10: Agosto | D10: =COUNTA(Mes!B59:B64) -> 6 | E10: =SUM(Mes!C59:C64) -> 600 | F10: 0 | G10: 0 | H10: 0 | I10: 0 | J10: =COUNTA(Mes!B153:B157) -> 5 | K10: =SUM(Mes!C153:C157) -> 500
A11: Setembro | D11: =COUNTA(Mes!B67:B70) -> 4 | E11: =SUM(Mes!C67:C70) -> 400 | F11: 0 | G11: 0 | H11: =COUNTA(Mes!B100:B103) -> 4 | I11: =SUM(Mes!C100:C103) -> 400 | J11: =COUNTA(Mes!B159:B163) -> 5 | K11: =SUM(Mes!C159:C163) -> 500
A12: Outubro | B12: =COUNTA(Mes!B7:B9) -> 3 | C12: =SUM(Mes!C7:C9) -> 150 | D12: =COUNTA(Mes!B73:B74) -> 2 | E12: =SUM(Mes!C73:C74) -> 100 | F12: 0 | G12: 0 | H12: =COUNTA(Mes!B105:B106) -> 2 | I12: =SUM(Mes!C105:C106) -> 200 | J12: =COUNTA(Mes!B165:B166) -> 2 | K12: =SUM(Mes!C165:C166) -> 200
A13: Novembro | B13: =COUNTA(Mes!B12:B14) -> 3 | C13: =SUM(Mes!C12:C14) -> 125 | D13: =COUNTA(Mes!B77) -> 1 | E13: =SUM(Mes!C77) -> 100 | F13: 0 | G13: 0 | H13: =COUNTA(Mes!B108) -> 1 | I13: =SUM(Mes!C108) -> 100 | J13: =COUNTA(Mes!B168:B172) -> 5 | K13: =SUM(Mes!C168:C172) -> 500
A14: Dezembro | B14: =COUNTA(Mes!B17:B18) -> 2 | C14: =SUM(Mes!C17:C18) -> 100 | D14: 0 | E14: 0 | F14: 0 | G14: 0 | H14: 0 | I14: 0 | J14: =COUNTA(Mes!B174:B176) -> 3 | K14: =SUM(Mes!C174:C176) -> 300
